<?xml version="1.0" ?>
<!-- Generated using onshape-to-robot -->
<!-- Onshape https://cad.onshape.com/documents/8f0c406ec917b7dcd4f2a559/w/98dc4b308a1cdd23475c2f79/e/5e1992bfb0f88c9dc7357fb3 -->
<robot name="urdf">
  <!-- Link base -->
  <link name="base">
    <inertial>
      <origin xyz="0.000371669 -0.0122024 0.041647" rpy="0 0 0"/>
      <mass value="0.0275445"/>
      <inertia ixx="2.09633e-05" ixy="-1.25235e-07" ixz="-5.4837e-08" iyy="9.13324e-06" iyz="-1.20902e-06" izz="2.71049e-05"/>
    </inertial>
    <!-- Part motor1_holder_v1 -->
    <visual>
      <origin xyz="9.94325e-05 -4.16334e-17 -0.00861064" rpy="1.5708 1.22144e-08 2.39214e-15"/>
      <geometry>
        <mesh filename="package://assets/motor1_holder_v1.stl"/>
      </geometry>
      <material name="motor1_holder_v1_material">
        <color rgba="0.262745 0.282353 0.301961 1"/>
      </material>
    </visual>
    <collision>
      <origin xyz="9.94325e-05 -4.16334e-17 -0.00861064" rpy="1.5708 1.22144e-08 2.39214e-15"/>
      <geometry>
        <mesh filename="package://assets/motor1_holder_v1.stl"/>
      </geometry>
    </collision>
    <!-- Part base_so101_v2 -->
    <visual>
      <origin xyz="3.04734e-19 0 -0.0085" rpy="1.5708 1.22144e-08 0"/>
      <geometry>
        <mesh filename="package://assets/base_so101_v2.stl"/>
      </geometry>
      <material name="base_so101_v2_material">
        <color rgba="0.262745 0.282353 0.301961 1"/>
      </material>
    </visual>
    <collision>
      <origin xyz="3.04734e-19 0 -0.0085" rpy="1.5708 1.22144e-08 0"/>
      <geometry>
        <mesh filename="package://assets/base_so101_v2.stl"/>
      </geometry>
    </collision>
    <!-- Part ge_27 -->
    <visual>
      <origin xyz="6.08275e-10 -0.04515 0.0413" rpy="-3.14159 -1.72327e-14 1.5708"/>
      <geometry>
        <mesh filename="package://assets/ge_27.stl"/>
      </geometry>
      <material name="ge_27_material">
        <color rgba="0.0980392 0.0980392 0.0980392 1"/>
      </material>
    </visual>
    <collision>
      <origin xyz="6.08275e-10 -0.04515 0.0413" rpy="-3.14159 -1.72327e-14 1.5708"/>
      <geometry>
        <mesh filename="package://assets/ge_27.stl"/>
      </geometry>
    </collision>
    <!-- Part xg_ziji_16 -->
    <visual>
      <origin xyz="6.81562e-10 -0.01965 0.0473" rpy="1.5708 -6.31089e-30 1.5708"/>
      <geometry>
        <mesh filename="package://assets/xg_ziji_16.stl"/>
      </geometry>
      <material name="xg_ziji_16_material">
        <color rgba="0.0980392 0.0980392 0.0980392 1"/>
      </material>
    </visual>
    <collision>
      <origin xyz="6.81562e-10 -0.01965 0.0473" rpy="1.5708 -6.31089e-30 1.5708"/>
      <geometry>
        <mesh filename="package://assets/xg_ziji_16.stl"/>
      </geometry>
    </collision>
    <!-- Part pcb_chazuo_92 -->
    <visual>
      <origin xyz="6.81562e-10 -0.01965 0.0473" rpy="1.5708 -6.31089e-30 1.5708"/>
      <geometry>
        <mesh filename="package://assets/pcb_chazuo_92.stl"/>
      </geometry>
      <material name="pcb_chazuo_92_material">
        <color rgba="0.0980392 0.0980392 0.0980392 1"/>
      </material>
    </visual>
    <collision>
      <origin xyz="6.81562e-10 -0.01965 0.0473" rpy="1.5708 -6.31089e-30 1.5708"/>
      <geometry>
        <mesh filename="package://assets/pcb_chazuo_92.stl"/>
      </geometry>
    </collision>
    <!-- Part zk_122 -->
    <visual>
      <origin xyz="6.81562e-10 -0.01965 0.0473" rpy="1.5708 -6.31089e-30 1.5708"/>
      <geometry>
        <mesh filename="package://assets/zk_122.stl"/>
      </geometry>
      <material name="zk_122_material">
        <color rgba="0.0980392 0.0980392 0.0980392 1"/>
      </material>
    </visual>
    <collision>
      <origin xyz="6.81562e-10 -0.01965 0.0473" rpy="1.5708 -6.31089e-30 1.5708"/>
      <geometry>
        <mesh filename="package://assets/zk_122.stl"/>
      </geometry>
    </collision>
    <!-- Part 金属舵盘_驱动__v2 -->
    <visual>
      <origin xyz="4.69031e-10 -0.05515 0.0299" rpy="1.5708 -3.63043e-14 1.5708"/>
      <geometry>
        <mesh filename="package://assets/金属舵盘_驱动__v2.stl"/>
      </geometry>
      <material name="金属舵盘_驱动__v2_material">
        <color rgba="0.960784 0.960784 0.964706 1"/>
      </material>
    </visual>
    <collision>
      <origin xyz="4.69031e-10 -0.05515 0.0299" rpy="1.5708 -3.63043e-14 1.5708"/>
      <geometry>
        <mesh filename="package://assets/金属舵盘_驱动__v2.stl"/>
      </geometry>
    </collision>
    <!-- Part 金属舵盘_从动__v2 -->
    <visual>
      <origin xyz="7.75598e-11 -0.03515 -0.00215" rpy="-1.5708 7.21645e-15 -1.5708"/>
      <geometry>
        <mesh filename="package://assets/金属舵盘_从动__v2.stl"/>
      </geometry>
      <material name="金属舵盘_从动__v2_material">
        <color rgba="0.960784 0.960784 0.964706 1"/>
      </material>
    </visual>
    <collision>
      <origin xyz="7.75598e-11 -0.03515 -0.00215" rpy="-1.5708 7.21645e-15 -1.5708"/>
      <geometry>
        <mesh filename="package://assets/金属舵盘_从动__v2.stl"/>
      </geometry>
    </collision>
    <!-- Part motor_1723_3 -->
    <visual>
      <origin xyz="-0.00125 -0.01965 0.02445" rpy="1.5708 -1.22144e-08 3.14159"/>
      <geometry>
        <mesh filename="package://assets/motor_1723_3.stl"/>
      </geometry>
      <material name="motor_1723_3_material">
        <color rgba="0.0980392 0.0980392 0.0980392 1"/>
      </material>
    </visual>
    <collision>
      <origin xyz="-0.00125 -0.01965 0.02445" rpy="1.5708 -1.22144e-08 3.14159"/>
      <geometry>
        <mesh filename="package://assets/motor_1723_3.stl"/>
      </geometry>
    </collision>
    <!-- Part sg_ziji_15 -->
    <visual>
      <origin xyz="6.81562e-10 -0.01965 0.0473" rpy="1.5708 -6.31089e-30 1.5708"/>
      <geometry>
        <mesh filename="package://assets/sg_ziji_15.stl"/>
      </geometry>
      <material name="sg_ziji_15_material">
        <color rgba="0.0980392 0.0980392 0.0980392 1"/>
      </material>
    </visual>
    <collision>
      <origin xyz="6.81562e-10 -0.01965 0.0473" rpy="1.5708 -6.31089e-30 1.5708"/>
      <geometry>
        <mesh filename="package://assets/sg_ziji_15.stl"/>
      </geometry>
    </collision>
  </link>
  <!-- Link base_pan -->
  <link name="base_pan">
    <inertial>
      <origin xyz="0 0 0" rpy="0 0 0"/>
      <mass value="1e-09"/>
      <inertia ixx="1e-09" ixy="0" ixz="0" iyy="1e-09" iyz="0" izz="1e-09"/>
    </inertial>
    <!-- Part part_1 -->
    <visual>
      <origin xyz="0.000236556 7.32214e-18 0.0182" rpy="3.14159 8.84314e-16 3.14159"/>
      <geometry>
        <mesh filename="package://assets/part_1.stl"/>
      </geometry>
      <material name="part_1_material">
        <color rgba="0.262745 0.282353 0.301961 1"/>
      </material>
    </visual>
    <collision>
      <origin xyz="0.000236556 7.32214e-18 0.0182" rpy="3.14159 8.84314e-16 3.14159"/>
      <geometry>
        <mesh filename="package://assets/part_1.stl"/>
      </geometry>
    </collision>
    <!-- Part ge_27_2 -->
    <visual>
      <origin xyz="-0.0126601 -0.004 -0.0252617" rpy="1.5708 5.37163e-13 3.14159"/>
      <geometry>
        <mesh filename="package://assets/ge_27.stl"/>
      </geometry>
      <material name="ge_27_2_material">
        <color rgba="0.0980392 0.0980392 0.0980392 1"/>
      </material>
    </visual>
    <collision>
      <origin xyz="-0.0126601 -0.004 -0.0252617" rpy="1.5708 5.37163e-13 3.14159"/>
      <geometry>
        <mesh filename="package://assets/ge_27.stl"/>
      </geometry>
    </collision>
    <!-- Part xg_ziji_16_2 -->
    <visual>
      <origin xyz="-0.0381601 -0.01 -0.0252617" rpy="-5.18819e-17 8.84314e-16 -3.14159"/>
      <geometry>
        <mesh filename="package://assets/xg_ziji_16.stl"/>
      </geometry>
      <material name="xg_ziji_16_2_material">
        <color rgba="0.0980392 0.0980392 0.0980392 1"/>
      </material>
    </visual>
    <collision>
      <origin xyz="-0.0381601 -0.01 -0.0252617" rpy="-5.18819e-17 8.84314e-16 -3.14159"/>
      <geometry>
        <mesh filename="package://assets/xg_ziji_16.stl"/>
      </geometry>
    </collision>
    <!-- Part pcb_chazuo_92_2 -->
    <visual>
      <origin xyz="-0.0381601 -0.01 -0.0252617" rpy="-5.18819e-17 8.84314e-16 -3.14159"/>
      <geometry>
        <mesh filename="package://assets/pcb_chazuo_92.stl"/>
      </geometry>
      <material name="pcb_chazuo_92_2_material">
        <color rgba="0.0980392 0.0980392 0.0980392 1"/>
      </material>
    </visual>
    <collision>
      <origin xyz="-0.0381601 -0.01 -0.0252617" rpy="-5.18819e-17 8.84314e-16 -3.14159"/>
      <geometry>
        <mesh filename="package://assets/pcb_chazuo_92.stl"/>
      </geometry>
    </collision>
    <!-- Part zk_122_2 -->
    <visual>
      <origin xyz="-0.0381601 -0.01 -0.0252617" rpy="-5.18819e-17 8.84314e-16 -3.14159"/>
      <geometry>
        <mesh filename="package://assets/zk_122.stl"/>
      </geometry>
      <material name="zk_122_2_material">
        <color rgba="0.0980392 0.0980392 0.0980392 1"/>
      </material>
    </visual>
    <collision>
      <origin xyz="-0.0381601 -0.01 -0.0252617" rpy="-5.18819e-17 8.84314e-16 -3.14159"/>
      <geometry>
        <mesh filename="package://assets/zk_122.stl"/>
      </geometry>
    </collision>
    <!-- Part 金属舵盘_驱动__v2_2 -->
    <visual>
      <origin xyz="-0.00266006 0.0074 -0.0252617" rpy="3.74777e-17 1.48109e-15 3.14159"/>
      <geometry>
        <mesh filename="package://assets/金属舵盘_驱动__v2.stl"/>
      </geometry>
      <material name="金属舵盘_驱动__v2_2_material">
        <color rgba="0.960784 0.960784 0.964706 1"/>
      </material>
    </visual>
    <collision>
      <origin xyz="-0.00266006 0.0074 -0.0252617" rpy="3.74777e-17 1.48109e-15 3.14159"/>
      <geometry>
        <mesh filename="package://assets/金属舵盘_驱动__v2.stl"/>
      </geometry>
    </collision>
    <!-- Part 金属舵盘_从动__v2_2 -->
    <visual>
      <origin xyz="-0.0226601 0.03945 -0.0252617" rpy="-2.433e-16 -1.20441e-15 -2.97672e-13"/>
      <geometry>
        <mesh filename="package://assets/金属舵盘_从动__v2.stl"/>
      </geometry>
      <material name="金属舵盘_从动__v2_2_material">
        <color rgba="0.960784 0.960784 0.964706 1"/>
      </material>
    </visual>
    <collision>
      <origin xyz="-0.0226601 0.03945 -0.0252617" rpy="-2.433e-16 -1.20441e-15 -2.97672e-13"/>
      <geometry>
        <mesh filename="package://assets/金属舵盘_从动__v2.stl"/>
      </geometry>
    </collision>
    <!-- Part motor_1723_3_2 -->
    <visual>
      <origin xyz="-0.0381601 0.01285 -0.0265117" rpy="-3.14159 1.5708 0"/>
      <geometry>
        <mesh filename="package://assets/motor_1723_3.stl"/>
      </geometry>
      <material name="motor_1723_3_2_material">
        <color rgba="0.0980392 0.0980392 0.0980392 1"/>
      </material>
    </visual>
    <collision>
      <origin xyz="-0.0381601 0.01285 -0.0265117" rpy="-3.14159 1.5708 0"/>
      <geometry>
        <mesh filename="package://assets/motor_1723_3.stl"/>
      </geometry>
    </collision>
    <!-- Part sg_ziji_15_2 -->
    <visual>
      <origin xyz="-0.0381601 -0.01 -0.0252617" rpy="-5.18819e-17 8.84314e-16 -3.14159"/>
      <geometry>
        <mesh filename="package://assets/sg_ziji_15.stl"/>
      </geometry>
      <material name="sg_ziji_15_2_material">
        <color rgba="0.0980392 0.0980392 0.0980392 1"/>
      </material>
    </visual>
    <collision>
      <origin xyz="-0.0381601 -0.01 -0.0252617" rpy="-5.18819e-17 8.84314e-16 -3.14159"/>
      <geometry>
        <mesh filename="package://assets/sg_ziji_15.stl"/>
      </geometry>
    </collision>
  </link>
  <!-- Link arm -->
  <link name="arm">
    <inertial>
      <origin xyz="0 0 0" rpy="0 0 0"/>
      <mass value="1e-09"/>
      <inertia ixx="1e-09" ixy="0" ixz="0" iyy="1e-09" iyz="0" izz="1e-09"/>
    </inertial>
    <!-- Part part_1_2 -->
    <visual>
      <origin xyz="-0.161258 0.005765 0.0175" rpy="1.11022e-16 -8.14037e-15 4.69954e-14"/>
      <geometry>
        <mesh filename="package://assets/part_1__2.stl"/>
      </geometry>
      <material name="part_1_2_material">
        <color rgba="0.262745 0.282353 0.301961 1"/>
      </material>
    </visual>
    <collision>
      <origin xyz="-0.161258 0.005765 0.0175" rpy="1.11022e-16 -8.14037e-15 4.69954e-14"/>
      <geometry>
        <mesh filename="package://assets/part_1__2.stl"/>
      </geometry>
    </collision>
    <!-- Part ge_27_3 -->
    <visual>
      <origin xyz="-0.161258 0.005765 0.01385" rpy="-3.96572e-13 2.64752e-13 -2.3755e-13"/>
      <geometry>
        <mesh filename="package://assets/ge_27.stl"/>
      </geometry>
      <material name="ge_27_3_material">
        <color rgba="0.0980392 0.0980392 0.0980392 1"/>
      </material>
    </visual>
    <collision>
      <origin xyz="-0.161258 0.005765 0.01385" rpy="-3.96572e-13 2.64752e-13 -2.3755e-13"/>
      <geometry>
        <mesh filename="package://assets/ge_27.stl"/>
      </geometry>
    </collision>
    <!-- Part xg_ziji_16_3 -->
    <visual>
      <origin xyz="-0.135758 0.005765 0.00785" rpy="-1.5708 -8.14037e-15 4.69954e-14"/>
      <geometry>
        <mesh filename="package://assets/xg_ziji_16.stl"/>
      </geometry>
      <material name="xg_ziji_16_3_material">
        <color rgba="0.0980392 0.0980392 0.0980392 1"/>
      </material>
    </visual>
    <collision>
      <origin xyz="-0.135758 0.005765 0.00785" rpy="-1.5708 -8.14037e-15 4.69954e-14"/>
      <geometry>
        <mesh filename="package://assets/xg_ziji_16.stl"/>
      </geometry>
    </collision>
    <!-- Part pcb_chazuo_92_3 -->
    <visual>
      <origin xyz="-0.135758 0.005765 0.00785" rpy="-1.5708 -8.14037e-15 4.69954e-14"/>
      <geometry>
        <mesh filename="package://assets/pcb_chazuo_92.stl"/>
      </geometry>
      <material name="pcb_chazuo_92_3_material">
        <color rgba="0.0980392 0.0980392 0.0980392 1"/>
      </material>
    </visual>
    <collision>
      <origin xyz="-0.135758 0.005765 0.00785" rpy="-1.5708 -8.14037e-15 4.69954e-14"/>
      <geometry>
        <mesh filename="package://assets/pcb_chazuo_92.stl"/>
      </geometry>
    </collision>
    <!-- Part zk_122_3 -->
    <visual>
      <origin xyz="-0.135758 0.005765 0.00785" rpy="-1.5708 -8.14037e-15 4.69954e-14"/>
      <geometry>
        <mesh filename="package://assets/zk_122.stl"/>
      </geometry>
      <material name="zk_122_3_material">
        <color rgba="0.0980392 0.0980392 0.0980392 1"/>
      </material>
    </visual>
    <collision>
      <origin xyz="-0.135758 0.005765 0.00785" rpy="-1.5708 -8.14037e-15 4.69954e-14"/>
      <geometry>
        <mesh filename="package://assets/zk_122.stl"/>
      </geometry>
    </collision>
    <!-- Part 金属舵盘_驱动__v2_3 -->
    <visual>
      <origin xyz="-0.171258 0.005765 0.02525" rpy="-1.5708 -7.44207e-14 1.28129e-16"/>
      <geometry>
        <mesh filename="package://assets/金属舵盘_驱动__v2.stl"/>
      </geometry>
      <material name="金属舵盘_驱动__v2_3_material">
        <color rgba="0.960784 0.960784 0.964706 1"/>
      </material>
    </visual>
    <collision>
      <origin xyz="-0.171258 0.005765 0.02525" rpy="-1.5708 -7.44207e-14 1.28129e-16"/>
      <geometry>
        <mesh filename="package://assets/金属舵盘_驱动__v2.stl"/>
      </geometry>
    </collision>
    <!-- Part 金属舵盘_从动__v2_3 -->
    <visual>
      <origin xyz="-0.151258 0.005765 0.0573" rpy="1.5708 1.16931e-14 -3.14159"/>
      <geometry>
        <mesh filename="package://assets/金属舵盘_从动__v2.stl"/>
      </geometry>
      <material name="金属舵盘_从动__v2_3_material">
        <color rgba="0.960784 0.960784 0.964706 1"/>
      </material>
    </visual>
    <collision>
      <origin xyz="-0.151258 0.005765 0.0573" rpy="1.5708 1.16931e-14 -3.14159"/>
      <geometry>
        <mesh filename="package://assets/金属舵盘_从动__v2.stl"/>
      </geometry>
    </collision>
    <!-- Part motor_1723_3_3 -->
    <visual>
      <origin xyz="-0.135758 0.004515 0.0307" rpy="-1.5708 -3.14693e-13 -1.5708"/>
      <geometry>
        <mesh filename="package://assets/motor_1723_3.stl"/>
      </geometry>
      <material name="motor_1723_3_3_material">
        <color rgba="0.0980392 0.0980392 0.0980392 1"/>
      </material>
    </visual>
    <collision>
      <origin xyz="-0.135758 0.004515 0.0307" rpy="-1.5708 -3.14693e-13 -1.5708"/>
      <geometry>
        <mesh filename="package://assets/motor_1723_3.stl"/>
      </geometry>
    </collision>
    <!-- Part sg_ziji_15_3 -->
    <visual>
      <origin xyz="-0.135758 0.005765 0.00785" rpy="-1.5708 -8.14037e-15 4.69954e-14"/>
      <geometry>
        <mesh filename="package://assets/sg_ziji_15.stl"/>
      </geometry>
      <material name="sg_ziji_15_3_material">
        <color rgba="0.0980392 0.0980392 0.0980392 1"/>
      </material>
    </visual>
    <collision>
      <origin xyz="-0.135758 0.005765 0.00785" rpy="-1.5708 -8.14037e-15 4.69954e-14"/>
      <geometry>
        <mesh filename="package://assets/sg_ziji_15.stl"/>
      </geometry>
    </collision>
  </link>
  <!-- Link forearm -->
  <link name="forearm">
    <inertial>
      <origin xyz="0 0 0" rpy="0 0 0"/>
      <mass value="1e-09"/>
      <inertia ixx="1e-09" ixy="0" ixz="0" iyy="1e-09" iyz="0" izz="1e-09"/>
    </inertial>
    <!-- Part part_1_3 -->
    <visual>
      <origin xyz="0.146885 -0.030202 0.0175" rpy="-1.31425e-15 -6.57252e-14 -3.14159"/>
      <geometry>
        <mesh filename="package://assets/part_1__3.stl"/>
      </geometry>
      <material name="part_1_3_material">
        <color rgba="0.262745 0.282353 0.301961 1"/>
      </material>
    </visual>
    <collision>
      <origin xyz="0.146885 -0.030202 0.0175" rpy="-1.31425e-15 -6.57252e-14 -3.14159"/>
      <geometry>
        <mesh filename="package://assets/part_1__3.stl"/>
      </geometry>
    </collision>
    <!-- Part ge_27_4 -->
    <visual>
      <origin xyz="0.146885 -0.030202 0.01395" rpy="6.18081e-13 -2.97762e-13 -3.14159"/>
      <geometry>
        <mesh filename="package://assets/ge_27.stl"/>
      </geometry>
      <material name="ge_27_4_material">
        <color rgba="0.0980392 0.0980392 0.0980392 1"/>
      </material>
    </visual>
    <collision>
      <origin xyz="0.146885 -0.030202 0.01395" rpy="6.18081e-13 -2.97762e-13 -3.14159"/>
      <geometry>
        <mesh filename="package://assets/ge_27.stl"/>
      </geometry>
    </collision>
    <!-- Part xg_ziji_16_4 -->
    <visual>
      <origin xyz="0.121385 -0.030202 0.00795" rpy="-1.5708 -6.57252e-14 -3.14159"/>
      <geometry>
        <mesh filename="package://assets/xg_ziji_16.stl"/>
      </geometry>
      <material name="xg_ziji_16_4_material">
        <color rgba="0.0980392 0.0980392 0.0980392 1"/>
      </material>
    </visual>
    <collision>
      <origin xyz="0.121385 -0.030202 0.00795" rpy="-1.5708 -6.57252e-14 -3.14159"/>
      <geometry>
        <mesh filename="package://assets/xg_ziji_16.stl"/>
      </geometry>
    </collision>
    <!-- Part pcb_chazuo_92_4 -->
    <visual>
      <origin xyz="0.121385 -0.030202 0.00795" rpy="-1.5708 -6.57252e-14 -3.14159"/>
      <geometry>
        <mesh filename="package://assets/pcb_chazuo_92.stl"/>
      </geometry>
      <material name="pcb_chazuo_92_4_material">
        <color rgba="0.0980392 0.0980392 0.0980392 1"/>
      </material>
    </visual>
    <collision>
      <origin xyz="0.121385 -0.030202 0.00795" rpy="-1.5708 -6.57252e-14 -3.14159"/>
      <geometry>
        <mesh filename="package://assets/pcb_chazuo_92.stl"/>
      </geometry>
    </collision>
    <!-- Part zk_122_4 -->
    <visual>
      <origin xyz="0.121385 -0.030202 0.00795" rpy="-1.5708 -6.57252e-14 -3.14159"/>
      <geometry>
        <mesh filename="package://assets/zk_122.stl"/>
      </geometry>
      <material name="zk_122_4_material">
        <color rgba="0.0980392 0.0980392 0.0980392 1"/>
      </material>
    </visual>
    <collision>
      <origin xyz="0.121385 -0.030202 0.00795" rpy="-1.5708 -6.57252e-14 -3.14159"/>
      <geometry>
        <mesh filename="package://assets/zk_122.stl"/>
      </geometry>
    </collision>
    <!-- Part 金属舵盘_驱动__v2_4 -->
    <visual>
      <origin xyz="0.156885 -0.030202 0.02535" rpy="-1.5708 -6.77236e-14 -3.14159"/>
      <geometry>
        <mesh filename="package://assets/金属舵盘_驱动__v2.stl"/>
      </geometry>
      <material name="金属舵盘_驱动__v2_4_material">
        <color rgba="0.960784 0.960784 0.964706 1"/>
      </material>
    </visual>
    <collision>
      <origin xyz="0.156885 -0.030202 0.02535" rpy="-1.5708 -6.77236e-14 -3.14159"/>
      <geometry>
        <mesh filename="package://assets/金属舵盘_驱动__v2.stl"/>
      </geometry>
    </collision>
    <!-- Part 金属舵盘_从动__v2_4 -->
    <visual>
      <origin xyz="0.136885 -0.030202 0.0574" rpy="1.5708 1.63758e-13 -3.70424e-13"/>
      <geometry>
        <mesh filename="package://assets/金属舵盘_从动__v2.stl"/>
      </geometry>
      <material name="金属舵盘_从动__v2_4_material">
        <color rgba="0.960784 0.960784 0.964706 1"/>
      </material>
    </visual>
    <collision>
      <origin xyz="0.136885 -0.030202 0.0574" rpy="1.5708 1.63758e-13 -3.70424e-13"/>
      <geometry>
        <mesh filename="package://assets/金属舵盘_从动__v2.stl"/>
      </geometry>
    </collision>
    <!-- Part motor_1723_3_4 -->
    <visual>
      <origin xyz="0.121385 -0.028952 0.0308" rpy="-1.5708 -5.04399e-14 1.5708"/>
      <geometry>
        <mesh filename="package://assets/motor_1723_3.stl"/>
      </geometry>
      <material name="motor_1723_3_4_material">
        <color rgba="0.0980392 0.0980392 0.0980392 1"/>
      </material>
    </visual>
    <collision>
      <origin xyz="0.121385 -0.028952 0.0308" rpy="-1.5708 -5.04399e-14 1.5708"/>
      <geometry>
        <mesh filename="package://assets/motor_1723_3.stl"/>
      </geometry>
    </collision>
    <!-- Part sg_ziji_15_4 -->
    <visual>
      <origin xyz="0.121385 -0.030202 0.00795" rpy="-1.5708 -6.57252e-14 -3.14159"/>
      <geometry>
        <mesh filename="package://assets/sg_ziji_15.stl"/>
      </geometry>
      <material name="sg_ziji_15_4_material">
        <color rgba="0.0980392 0.0980392 0.0980392 1"/>
      </material>
    </visual>
    <collision>
      <origin xyz="0.121385 -0.030202 0.00795" rpy="-1.5708 -6.57252e-14 -3.14159"/>
      <geometry>
        <mesh filename="package://assets/sg_ziji_15.stl"/>
      </geometry>
    </collision>
  </link>
  <!-- Link wrist_raise -->
  <link name="wrist_raise">
    <inertial>
      <origin xyz="0 0 0" rpy="0 0 0"/>
      <mass value="1e-09"/>
      <inertia ixx="1e-09" ixy="0" ixz="0" iyy="1e-09" iyz="0" izz="1e-09"/>
    </inertial>
    <!-- Part part_1_4 -->
    <visual>
      <origin xyz="0.0411343 0.044825 0.0175" rpy="-1.5708 -2.12167e-29 0"/>
      <geometry>
        <mesh filename="package://assets/part_1__4.stl"/>
      </geometry>
      <material name="part_1_4_material">
        <color rgba="0.262745 0.282353 0.301961 1"/>
      </material>
    </visual>
    <collision>
      <origin xyz="0.0411343 0.044825 0.0175" rpy="-1.5708 -2.12167e-29 0"/>
      <geometry>
        <mesh filename="package://assets/part_1__4.stl"/>
      </geometry>
    </collision>
    <!-- Part ge_27_5 -->
    <visual>
      <origin xyz="0.0411343 0.041275 0.0175" rpy="-1.5708 -1.19127e-13 -2.07843e-14"/>
      <geometry>
        <mesh filename="package://assets/ge_27.stl"/>
      </geometry>
      <material name="ge_27_5_material">
        <color rgba="0.0980392 0.0980392 0.0980392 1"/>
      </material>
    </visual>
    <collision>
      <origin xyz="0.0411343 0.041275 0.0175" rpy="-1.5708 -1.19127e-13 -2.07843e-14"/>
      <geometry>
        <mesh filename="package://assets/ge_27.stl"/>
      </geometry>
    </collision>
    <!-- Part xg_ziji_16_5 -->
    <visual>
      <origin xyz="0.0666343 0.035275 0.0175" rpy="-3.14159 4.62977e-25 -1.66531e-16"/>
      <geometry>
        <mesh filename="package://assets/xg_ziji_16.stl"/>
      </geometry>
      <material name="xg_ziji_16_5_material">
        <color rgba="0.0980392 0.0980392 0.0980392 1"/>
      </material>
    </visual>
    <collision>
      <origin xyz="0.0666343 0.035275 0.0175" rpy="-3.14159 4.62977e-25 -1.66531e-16"/>
      <geometry>
        <mesh filename="package://assets/xg_ziji_16.stl"/>
      </geometry>
    </collision>
    <!-- Part pcb_chazuo_92_5 -->
    <visual>
      <origin xyz="0.0666343 0.035275 0.0175" rpy="-3.14159 4.62977e-25 -1.66531e-16"/>
      <geometry>
        <mesh filename="package://assets/pcb_chazuo_92.stl"/>
      </geometry>
      <material name="pcb_chazuo_92_5_material">
        <color rgba="0.0980392 0.0980392 0.0980392 1"/>
      </material>
    </visual>
    <collision>
      <origin xyz="0.0666343 0.035275 0.0175" rpy="-3.14159 4.62977e-25 -1.66531e-16"/>
      <geometry>
        <mesh filename="package://assets/pcb_chazuo_92.stl"/>
      </geometry>
    </collision>
    <!-- Part zk_122_5 -->
    <visual>
      <origin xyz="0.0666343 0.035275 0.0175" rpy="-3.14159 4.62977e-25 -1.66531e-16"/>
      <geometry>
        <mesh filename="package://assets/zk_122.stl"/>
      </geometry>
      <material name="zk_122_5_material">
        <color rgba="0.0980392 0.0980392 0.0980392 1"/>
      </material>
    </visual>
    <collision>
      <origin xyz="0.0666343 0.035275 0.0175" rpy="-3.14159 4.62977e-25 -1.66531e-16"/>
      <geometry>
        <mesh filename="package://assets/zk_122.stl"/>
      </geometry>
    </collision>
    <!-- Part 金属舵盘_驱动__v2_5 -->
    <visual>
      <origin xyz="0.0311343 0.052675 0.0175" rpy="-3.14159 -7.77156e-16 1.66534e-15"/>
      <geometry>
        <mesh filename="package://assets/金属舵盘_驱动__v2.stl"/>
      </geometry>
      <material name="金属舵盘_驱动__v2_5_material">
        <color rgba="0.960784 0.960784 0.964706 1"/>
      </material>
    </visual>
    <collision>
      <origin xyz="0.0311343 0.052675 0.0175" rpy="-3.14159 -7.77156e-16 1.66534e-15"/>
      <geometry>
        <mesh filename="package://assets/金属舵盘_驱动__v2.stl"/>
      </geometry>
    </collision>
    <!-- Part 金属舵盘_从动__v2_5 -->
    <visual>
      <origin xyz="0.0511343 0.084725 0.0175" rpy="-3.14159 -6.77236e-15 3.14159"/>
      <geometry>
        <mesh filename="package://assets/金属舵盘_从动__v2.stl"/>
      </geometry>
      <material name="金属舵盘_从动__v2_5_material">
        <color rgba="0.960784 0.960784 0.964706 1"/>
      </material>
    </visual>
    <collision>
      <origin xyz="0.0511343 0.084725 0.0175" rpy="-3.14159 -6.77236e-15 3.14159"/>
      <geometry>
        <mesh filename="package://assets/金属舵盘_从动__v2.stl"/>
      </geometry>
    </collision>
    <!-- Part motor_1723_3_5 -->
    <visual>
      <origin xyz="0.0666343 0.058125 0.01875" rpy="-3.14159 -1.5708 0"/>
      <geometry>
        <mesh filename="package://assets/motor_1723_3.stl"/>
      </geometry>
      <material name="motor_1723_3_5_material">
        <color rgba="0.0980392 0.0980392 0.0980392 1"/>
      </material>
    </visual>
    <collision>
      <origin xyz="0.0666343 0.058125 0.01875" rpy="-3.14159 -1.5708 0"/>
      <geometry>
        <mesh filename="package://assets/motor_1723_3.stl"/>
      </geometry>
    </collision>
    <!-- Part sg_ziji_15_5 -->
    <visual>
      <origin xyz="0.0666343 0.035275 0.0175" rpy="-3.14159 4.62977e-25 -1.66531e-16"/>
      <geometry>
        <mesh filename="package://assets/sg_ziji_15.stl"/>
      </geometry>
      <material name="sg_ziji_15_5_material">
        <color rgba="0.0980392 0.0980392 0.0980392 1"/>
      </material>
    </visual>
    <collision>
      <origin xyz="0.0666343 0.035275 0.0175" rpy="-3.14159 4.62977e-25 -1.66531e-16"/>
      <geometry>
        <mesh filename="package://assets/sg_ziji_15.stl"/>
      </geometry>
    </collision>
  </link>
  <!-- Link wrist_pan -->
  <link name="wrist_pan">
    <inertial>
      <origin xyz="0 0 0" rpy="0 0 0"/>
      <mass value="1e-09"/>
      <inertia ixx="1e-09" ixy="0" ixz="0" iyy="1e-09" iyz="0" izz="1e-09"/>
    </inertial>
    <!-- Part part_1_5 -->
    <visual>
      <origin xyz="0 0.038016 -0.0312" rpy="3.14159 3.88959e-25 -1.93425e-29"/>
      <geometry>
        <mesh filename="package://assets/part_1__5.stl"/>
      </geometry>
      <material name="part_1_5_material">
        <color rgba="0.262745 0.282353 0.301961 1"/>
      </material>
    </visual>
    <collision>
      <origin xyz="0 0.038016 -0.0312" rpy="3.14159 3.88959e-25 -1.93425e-29"/>
      <geometry>
        <mesh filename="package://assets/part_1__5.stl"/>
      </geometry>
    </collision>
    <!-- Part ge_27_6 -->
    <visual>
      <origin xyz="3.81538e-05 0.043216 -0.02" rpy="1.5708 1.5708 0"/>
      <geometry>
        <mesh filename="package://assets/ge_27.stl"/>
      </geometry>
      <material name="ge_27_6_material">
        <color rgba="0.0980392 0.0980392 0.0980392 1"/>
      </material>
    </visual>
    <collision>
      <origin xyz="3.81538e-05 0.043216 -0.02" rpy="1.5708 1.5708 0"/>
      <geometry>
        <mesh filename="package://assets/ge_27.stl"/>
      </geometry>
    </collision>
    <!-- Part xg_ziji_16_6 -->
    <visual>
      <origin xyz="3.81538e-05 0.049216 -0.0455" rpy="2.94764e-14 1.5708 0"/>
      <geometry>
        <mesh filename="package://assets/xg_ziji_16.stl"/>
      </geometry>
      <material name="xg_ziji_16_6_material">
        <color rgba="0.0980392 0.0980392 0.0980392 1"/>
      </material>
    </visual>
    <collision>
      <origin xyz="3.81538e-05 0.049216 -0.0455" rpy="2.94764e-14 1.5708 0"/>
      <geometry>
        <mesh filename="package://assets/xg_ziji_16.stl"/>
      </geometry>
    </collision>
    <!-- Part pcb_chazuo_92_6 -->
    <visual>
      <origin xyz="3.81538e-05 0.049216 -0.0455" rpy="2.94764e-14 1.5708 0"/>
      <geometry>
        <mesh filename="package://assets/pcb_chazuo_92.stl"/>
      </geometry>
      <material name="pcb_chazuo_92_6_material">
        <color rgba="0.0980392 0.0980392 0.0980392 1"/>
      </material>
    </visual>
    <collision>
      <origin xyz="3.81538e-05 0.049216 -0.0455" rpy="2.94764e-14 1.5708 0"/>
      <geometry>
        <mesh filename="package://assets/pcb_chazuo_92.stl"/>
      </geometry>
    </collision>
    <!-- Part zk_122_6 -->
    <visual>
      <origin xyz="3.81538e-05 0.049216 -0.0455" rpy="2.94764e-14 1.5708 0"/>
      <geometry>
        <mesh filename="package://assets/zk_122.stl"/>
      </geometry>
      <material name="zk_122_6_material">
        <color rgba="0.0980392 0.0980392 0.0980392 1"/>
      </material>
    </visual>
    <collision>
      <origin xyz="3.81538e-05 0.049216 -0.0455" rpy="2.94764e-14 1.5708 0"/>
      <geometry>
        <mesh filename="package://assets/zk_122.stl"/>
      </geometry>
    </collision>
    <!-- Part 金属舵盘_驱动__v2_6 -->
    <visual>
      <origin xyz="3.81538e-05 0.031816 -0.01" rpy="2.86993e-14 1.5708 0"/>
      <geometry>
        <mesh filename="package://assets/金属舵盘_驱动__v2.stl"/>
      </geometry>
      <material name="金属舵盘_驱动__v2_6_material">
        <color rgba="0.960784 0.960784 0.964706 1"/>
      </material>
    </visual>
    <collision>
      <origin xyz="3.81538e-05 0.031816 -0.01" rpy="2.86993e-14 1.5708 0"/>
      <geometry>
        <mesh filename="package://assets/金属舵盘_驱动__v2.stl"/>
      </geometry>
    </collision>
    <!-- Part 金属舵盘_从动__v2_6 -->
    <visual>
      <origin xyz="3.81538e-05 -0.000234 -0.03" rpy="-3.14159 -1.5708 0"/>
      <geometry>
        <mesh filename="package://assets/金属舵盘_从动__v2.stl"/>
      </geometry>
      <material name="金属舵盘_从动__v2_6_material">
        <color rgba="0.960784 0.960784 0.964706 1"/>
      </material>
    </visual>
    <collision>
      <origin xyz="3.81538e-05 -0.000234 -0.03" rpy="-3.14159 -1.5708 0"/>
      <geometry>
        <mesh filename="package://assets/金属舵盘_从动__v2.stl"/>
      </geometry>
    </collision>
    <!-- Part motor_1723_3_6 -->
    <visual>
      <origin xyz="-0.00121185 0.026366 -0.0455" rpy="-3.14159 2.34304e-13 3.14159"/>
      <geometry>
        <mesh filename="package://assets/motor_1723_3.stl"/>
      </geometry>
      <material name="motor_1723_3_6_material">
        <color rgba="0.0980392 0.0980392 0.0980392 1"/>
      </material>
    </visual>
    <collision>
      <origin xyz="-0.00121185 0.026366 -0.0455" rpy="-3.14159 2.34304e-13 3.14159"/>
      <geometry>
        <mesh filename="package://assets/motor_1723_3.stl"/>
      </geometry>
    </collision>
    <!-- Part sg_ziji_15_6 -->
    <visual>
      <origin xyz="3.81538e-05 0.049216 -0.0455" rpy="2.94764e-14 1.5708 0"/>
      <geometry>
        <mesh filename="package://assets/sg_ziji_15.stl"/>
      </geometry>
      <material name="sg_ziji_15_6_material">
        <color rgba="0.0980392 0.0980392 0.0980392 1"/>
      </material>
    </visual>
    <collision>
      <origin xyz="3.81538e-05 0.049216 -0.0455" rpy="2.94764e-14 1.5708 0"/>
      <geometry>
        <mesh filename="package://assets/sg_ziji_15.stl"/>
      </geometry>
    </collision>
  </link>
  <!-- Link gripper_base -->
  <link name="gripper_base">
    <inertial>
      <origin xyz="0 0 0" rpy="0 0 0"/>
      <mass value="1e-09"/>
      <inertia ixx="1e-09" ixy="0" ixz="0" iyy="1e-09" iyz="0" izz="1e-09"/>
    </inertial>
    <!-- Part compliantgripper -->
    <visual>
      <origin xyz="-0.0142 0.00372 -0.0475" rpy="1.43831e-14 1.30218e-14 1.5708"/>
      <geometry>
        <mesh filename="package://assets/compliantgripper.stl"/>
      </geometry>
      <material name="compliantgripper_material">
        <color rgba="0.231373 0.380392 0.705882 1"/>
      </material>
    </visual>
    <collision>
      <origin xyz="-0.0142 0.00372 -0.0475" rpy="1.43831e-14 1.30218e-14 1.5708"/>
      <geometry>
        <mesh filename="package://assets/compliantgripper.stl"/>
      </geometry>
    </collision>
    <!-- Part part_1_6 -->
    <visual>
      <origin xyz="-1.38778e-17 0 -0.008" rpy="1.5708 1.39113e-14 2.30671e-14"/>
      <geometry>
        <mesh filename="package://assets/part_1__6.stl"/>
      </geometry>
      <material name="part_1_6_material">
        <color rgba="0.262745 0.282353 0.301961 1"/>
      </material>
    </visual>
    <collision>
      <origin xyz="-1.38778e-17 0 -0.008" rpy="1.5708 1.39113e-14 2.30671e-14"/>
      <geometry>
        <mesh filename="package://assets/part_1__6.stl"/>
      </geometry>
    </collision>
    <!-- Part ge_27_7 -->
    <visual>
      <origin xyz="-0.0038 -0.018 -0.0245" rpy="1.5708 1.03075e-14 1.5708"/>
      <geometry>
        <mesh filename="package://assets/ge_27.stl"/>
      </geometry>
      <material name="ge_27_7_material">
        <color rgba="0.0980392 0.0980392 0.0980392 1"/>
      </material>
    </visual>
    <collision>
      <origin xyz="-0.0038 -0.018 -0.0245" rpy="1.5708 1.03075e-14 1.5708"/>
      <geometry>
        <mesh filename="package://assets/ge_27.stl"/>
      </geometry>
    </collision>
    <!-- Part xg_ziji_16_7 -->
    <visual>
      <origin xyz="-0.0098 0.0075 -0.0245" rpy="1.3717e-14 1.30504e-14 1.5708"/>
      <geometry>
        <mesh filename="package://assets/xg_ziji_16.stl"/>
      </geometry>
      <material name="xg_ziji_16_7_material">
        <color rgba="0.0980392 0.0980392 0.0980392 1"/>
      </material>
    </visual>
    <collision>
      <origin xyz="-0.0098 0.0075 -0.0245" rpy="1.3717e-14 1.30504e-14 1.5708"/>
      <geometry>
        <mesh filename="package://assets/xg_ziji_16.stl"/>
      </geometry>
    </collision>
    <!-- Part pcb_chazuo_92_7 -->
    <visual>
      <origin xyz="-0.0098 0.0075 -0.0245" rpy="1.3717e-14 1.30504e-14 1.5708"/>
      <geometry>
        <mesh filename="package://assets/pcb_chazuo_92.stl"/>
      </geometry>
      <material name="pcb_chazuo_92_7_material">
        <color rgba="0.0980392 0.0980392 0.0980392 1"/>
      </material>
    </visual>
    <collision>
      <origin xyz="-0.0098 0.0075 -0.0245" rpy="1.3717e-14 1.30504e-14 1.5708"/>
      <geometry>
        <mesh filename="package://assets/pcb_chazuo_92.stl"/>
      </geometry>
    </collision>
    <!-- Part zk_122_7 -->
    <visual>
      <origin xyz="-0.0098 0.0075 -0.0245" rpy="1.3717e-14 1.30504e-14 1.5708"/>
      <geometry>
        <mesh filename="package://assets/zk_122.stl"/>
      </geometry>
      <material name="zk_122_7_material">
        <color rgba="0.0980392 0.0980392 0.0980392 1"/>
      </material>
    </visual>
    <collision>
      <origin xyz="-0.0098 0.0075 -0.0245" rpy="1.3717e-14 1.30504e-14 1.5708"/>
      <geometry>
        <mesh filename="package://assets/zk_122.stl"/>
      </geometry>
    </collision>
    <!-- Part 金属舵盘_驱动__v2_7 -->
    <visual>
      <origin xyz="0.0076 -0.028 -0.0245" rpy="1.36615e-14 1.20247e-14 1.5708"/>
      <geometry>
        <mesh filename="package://assets/金属舵盘_驱动__v2.stl"/>
      </geometry>
      <material name="金属舵盘_驱动__v2_7_material">
        <color rgba="0.960784 0.960784 0.964706 1"/>
      </material>
    </visual>
    <collision>
      <origin xyz="0.0076 -0.028 -0.0245" rpy="1.36615e-14 1.20247e-14 1.5708"/>
      <geometry>
        <mesh filename="package://assets/金属舵盘_驱动__v2.stl"/>
      </geometry>
    </collision>
    <!-- Part 金属舵盘_从动__v2_7 -->
    <visual>
      <origin xyz="0.03965 -0.008 -0.0245" rpy="8.10406e-14 -4.86831e-14 -1.5708"/>
      <geometry>
        <mesh filename="package://assets/金属舵盘_从动__v2.stl"/>
      </geometry>
      <material name="金属舵盘_从动__v2_7_material">
        <color rgba="0.960784 0.960784 0.964706 1"/>
      </material>
    </visual>
    <collision>
      <origin xyz="0.03965 -0.008 -0.0245" rpy="8.10406e-14 -4.86831e-14 -1.5708"/>
      <geometry>
        <mesh filename="package://assets/金属舵盘_从动__v2.stl"/>
      </geometry>
    </collision>
    <!-- Part motor_1723_3_7 -->
    <visual>
      <origin xyz="0.01305 0.0075 -0.02575" rpy="-1.5708 1.5708 0"/>
      <geometry>
        <mesh filename="package://assets/motor_1723_3.stl"/>
      </geometry>
      <material name="motor_1723_3_7_material">
        <color rgba="0.0980392 0.0980392 0.0980392 1"/>
      </material>
    </visual>
    <collision>
      <origin xyz="0.01305 0.0075 -0.02575" rpy="-1.5708 1.5708 0"/>
      <geometry>
        <mesh filename="package://assets/motor_1723_3.stl"/>
      </geometry>
    </collision>
    <!-- Part sg_ziji_15_7 -->
    <visual>
      <origin xyz="-0.0098 0.0075 -0.0245" rpy="1.3717e-14 1.30504e-14 1.5708"/>
      <geometry>
        <mesh filename="package://assets/sg_ziji_15.stl"/>
      </geometry>
      <material name="sg_ziji_15_7_material">
        <color rgba="0.0980392 0.0980392 0.0980392 1"/>
      </material>
    </visual>
    <collision>
      <origin xyz="-0.0098 0.0075 -0.0245" rpy="1.3717e-14 1.30504e-14 1.5708"/>
      <geometry>
        <mesh filename="package://assets/sg_ziji_15.stl"/>
      </geometry>
    </collision>
  </link>
  <!-- Link gripper_move -->
  <link name="gripper_move">
    <inertial>
      <origin xyz="0 0 0" rpy="0 0 0"/>
      <mass value="1e-09"/>
      <inertia ixx="1e-09" ixy="0" ixz="0" iyy="1e-09" iyz="0" izz="1e-09"/>
    </inertial>
    <!-- Part compliantgripper_2 -->
    <visual>
      <origin xyz="0.02315 0.02014 0.031" rpy="1.5708 6.3291e-16 -1.5708"/>
      <geometry>
        <mesh filename="package://assets/compliantgripper.stl"/>
      </geometry>
      <material name="compliantgripper_2_material">
        <color rgba="0.231373 0.380392 0.705882 1"/>
      </material>
    </visual>
    <collision>
      <origin xyz="0.02315 0.02014 0.031" rpy="1.5708 6.3291e-16 -1.5708"/>
      <geometry>
        <mesh filename="package://assets/compliantgripper.stl"/>
      </geometry>
    </collision>
    <!-- Part part_1_7 -->
    <visual>
      <origin xyz="0.00115 3.46945e-18 0" rpy="1.5708 5.76237e-31 -5.16292e-30"/>
      <geometry>
        <mesh filename="package://assets/part_1__7.stl"/>
      </geometry>
      <material name="part_1_7_material">
        <color rgba="0.262745 0.282353 0.301961 1"/>
      </material>
    </visual>
    <collision>
      <origin xyz="0.00115 3.46945e-18 0" rpy="1.5708 5.76237e-31 -5.16292e-30"/>
      <geometry>
        <mesh filename="package://assets/part_1__7.stl"/>
      </geometry>
    </collision>
  </link>
  <!-- Joint from gripper_base to gripper_move -->
  <joint name="gripper" type="revolute">
    <origin xyz="-0.0194 -0.018 -0.0245" rpy="-2.24351e-14 1.5708 0"/>
    <parent link="gripper_base"/>
    <child link="gripper_move"/>
    <axis xyz="0 0 1"/>
    <limit effort="10" velocity="10" lower="-1.5708" upper="2.40696e-13"/>
  </joint>
  <!-- Joint from wrist_pan to gripper_base -->
  <joint name="wrist_rotate" type="revolute">
    <origin xyz="3.81538e-05 0.058816 -0.02" rpy="1.5708 1.5708 0"/>
    <parent link="wrist_pan"/>
    <child link="gripper_base"/>
    <axis xyz="0 0 1"/>
    <limit effort="10" velocity="10" lower="-3.14159" upper="3.14159"/>
  </joint>
  <!-- Joint from wrist_raise to wrist_pan -->
  <joint name="wrist_pan" type="revolute">
    <origin xyz="0.0411343 0.025675 0.0175" rpy="-1.5708 -1.5708 0"/>
    <parent link="wrist_raise"/>
    <child link="wrist_pan"/>
    <axis xyz="0 0 1"/>
    <limit effort="10" velocity="10" lower="-1.5708" upper="1.5708"/>
  </joint>
  <!-- Joint from forearm to wrist_raise -->
  <joint name="wrist_raise" type="revolute">
    <origin xyz="0.146885 -0.030202 0.03615" rpy="-3.14159 6.57252e-14 8.55553e-15"/>
    <parent link="forearm"/>
    <child link="wrist_raise"/>
    <axis xyz="0 0 1"/>
    <limit effort="10" velocity="10" lower="-2.26893" upper="1.91986"/>
  </joint>
  <!-- Joint from arm to forearm -->
  <joint name="elbow_raise" type="revolute">
    <origin xyz="-0.161258 0.005765 -0.00175" rpy="-1.31425e-15 -7.44207e-14 1.28129e-16"/>
    <parent link="arm"/>
    <child link="forearm"/>
    <axis xyz="0 0 1"/>
    <limit effort="10" velocity="10" lower="-2.87979" upper="6.66134e-14"/>
  </joint>
  <!-- Joint from base_pan to arm -->
  <joint name="shoulder_raise" type="revolute">
    <origin xyz="-0.0126601 -0.0196 -0.0252617" rpy="1.5708 1.48109e-15 3.14159"/>
    <parent link="base_pan"/>
    <child link="arm"/>
    <axis xyz="0 0 1"/>
    <limit effort="10" velocity="10" lower="0" upper="3.49066"/>
  </joint>
  <!-- Joint from base to base_pan -->
  <joint name="shoulder_pan" type="revolute">
    <origin xyz="7.98819e-10 -0.04515 0.0569" rpy="-3.14159 -3.63043e-14 1.5708"/>
    <parent link="base"/>
    <child link="base_pan"/>
    <axis xyz="0 0 1"/>
    <limit effort="10" velocity="10" lower="-1.91986" upper="1.91986"/>
  </joint>
</robot>
